{
  "url": "https://api.github.com/repos/facebook/react/issues/11334",
  "repository_url": "https://api.github.com/repos/facebook/react",
  "labels_url": "https://api.github.com/repos/facebook/react/issues/11334/labels{/name}",
  "comments_url": "https://api.github.com/repos/facebook/react/issues/11334/comments",
  "events_url": "https://api.github.com/repos/facebook/react/issues/11334/events",
  "html_url": "https://github.com/facebook/react/issues/11334",
  "id": 267552419,
  "node_id": "MDU6SXNzdWUyNjc1NTI0MTk=",
  "number": 11334,
  "title": "componentDidCatch is not getting called when there is an error in promise",
  "user": {
    "login": "john1jan",
    "id": 4264813,
    "node_id": "MDQ6VXNlcjQyNjQ4MTM=",
    "avatar_url": "https://avatars2.githubusercontent.com/u/4264813?v=4",
    "gravatar_id": "",
    "url": "https://api.github.com/users/john1jan",
    "html_url": "https://github.com/john1jan",
    "followers_url": "https://api.github.com/users/john1jan/followers",
    "following_url": "https://api.github.com/users/john1jan/following{/other_user}",
    "gists_url": "https://api.github.com/users/john1jan/gists{/gist_id}",
    "starred_url": "https://api.github.com/users/john1jan/starred{/owner}{/repo}",
    "subscriptions_url": "https://api.github.com/users/john1jan/subscriptions",
    "organizations_url": "https://api.github.com/users/john1jan/orgs",
    "repos_url": "https://api.github.com/users/john1jan/repos",
    "events_url": "https://api.github.com/users/john1jan/events{/privacy}",
    "received_events_url": "https://api.github.com/users/john1jan/received_events",
    "type": "User",
    "site_admin": false
  },
  "labels": [

  ],
  "state": "closed",
  "locked": false,
  "assignee": null,
  "assignees": [

  ],
  "milestone": null,
  "comments": 13,
  "created_at": "2017-10-23T06:17:56Z",
  "updated_at": "2019-08-19T19:57:31Z",
  "closed_at": "2017-10-23T13:20:48Z",
  "author_association": "NONE",
  "body": " As per the new react 16 release [doc](https://reactjs.org/blog/2017/07/26/error-handling-in-react-16.html)  it says \r\n\r\n\"**React 16 prints all errors that occurred during rendering to the console in development, even if the application accidentally swallows them.**\"\r\n\r\nI have a Parent component and a Child component. I have triggered an error in **then** block of promise. But it will call catch method of the promise, componentDidCatch of parent is not getting called. I am not sure  whether this the expected behaviour. \r\n\r\nHere is the jsfiddle https://jsfiddle.net/john1jan/Luktwrdm/14/\r\n",
  "closed_by": {
    "login": "gaearon",
    "id": 810438,
    "node_id": "MDQ6VXNlcjgxMDQzOA==",
    "avatar_url": "https://avatars0.githubusercontent.com/u/810438?v=4",
    "gravatar_id": "",
    "url": "https://api.github.com/users/gaearon",
    "html_url": "https://github.com/gaearon",
    "followers_url": "https://api.github.com/users/gaearon/followers",
    "following_url": "https://api.github.com/users/gaearon/following{/other_user}",
    "gists_url": "https://api.github.com/users/gaearon/gists{/gist_id}",
    "starred_url": "https://api.github.com/users/gaearon/starred{/owner}{/repo}",
    "subscriptions_url": "https://api.github.com/users/gaearon/subscriptions",
    "organizations_url": "https://api.github.com/users/gaearon/orgs",
    "repos_url": "https://api.github.com/users/gaearon/repos",
    "events_url": "https://api.github.com/users/gaearon/events{/privacy}",
    "received_events_url": "https://api.github.com/users/gaearon/received_events",
    "type": "User",
    "site_admin": false
  }
}
