{
  "url": "https://api.github.com/repos/facebook/react/issues/17031",
  "repository_url": "https://api.github.com/repos/facebook/react",
  "labels_url": "https://api.github.com/repos/facebook/react/issues/17031/labels{/name}",
  "comments_url": "https://api.github.com/repos/facebook/react/issues/17031/comments",
  "events_url": "https://api.github.com/repos/facebook/react/issues/17031/events",
  "html_url": "https://github.com/facebook/react/issues/17031",
  "id": 503387673,
  "node_id": "MDU6SXNzdWU1MDMzODc2NzM=",
  "number": 17031,
  "title": "Error Boundary and Errors Thrown by a Promise",
  "user": {
    "login": "dcs3spp",
    "id": 12863448,
    "node_id": "MDQ6VXNlcjEyODYzNDQ4",
    "avatar_url": "https://avatars3.githubusercontent.com/u/12863448?v=4",
    "gravatar_id": "",
    "url": "https://api.github.com/users/dcs3spp",
    "html_url": "https://github.com/dcs3spp",
    "followers_url": "https://api.github.com/users/dcs3spp/followers",
    "following_url": "https://api.github.com/users/dcs3spp/following{/other_user}",
    "gists_url": "https://api.github.com/users/dcs3spp/gists{/gist_id}",
    "starred_url": "https://api.github.com/users/dcs3spp/starred{/owner}{/repo}",
    "subscriptions_url": "https://api.github.com/users/dcs3spp/subscriptions",
    "organizations_url": "https://api.github.com/users/dcs3spp/orgs",
    "repos_url": "https://api.github.com/users/dcs3spp/repos",
    "events_url": "https://api.github.com/users/dcs3spp/events{/privacy}",
    "received_events_url": "https://api.github.com/users/dcs3spp/received_events",
    "type": "User",
    "site_admin": false
  },
  "labels": [

  ],
  "state": "open",
  "locked": false,
  "assignee": null,
  "assignees": [

  ],
  "milestone": null,
  "comments": 0,
  "created_at": "2019-10-07T11:19:10Z",
  "updated_at": "2019-10-07T11:19:10Z",
  "closed_at": null,
  "author_association": "NONE",
  "body": "Hi,\r\n\r\nI am learning react and trying to get an Error Boundary component to catch an error from a promise. In the _componentDidMount_ method of a child component I am making an axios request. The only way I can get the Error Boundary component to catch the error from the promise is to to use this.setState(()=> {throw error}) in the catch handler. If I do not use the setState approach and rethrow the error in the catch handler then the Error Boundary component does not catch the error.\r\n\r\nIs the setState approach the recommended approach for getting an Error Boundary component to catch a promise or is there a better way? Is there any documentation for Error Boundary components recognising errors thrown by a promise?\r\n \r\n```ts\r\ncomponentDidMount(): void {\r\n    console.log('CourseList::componentDidMount');\r\n\r\n    const dataSource: RestDataCourse = new RestDataCourse();\r\n    dataSource\r\n      .getCourses()\r\n      .then(courseList => {\r\n        this.setState({ courses: courseList });\r\n      })\r\n      .catch(error => {\r\n        console.error(`Error retrieving courses => ${JSON.stringify(error)}`);\r\n        this.setState(() => {\r\n          throw error;\r\n        });\r\n        // throw error\r\n      });\r\n  }\r\n```\r\n",
  "closed_by": null
}
